[2024-06-24T22:03:42.984+0000] {local_task_job_runner.py:120} INFO - ::group::Pre task execution logs
[2024-06-24T22:03:42.990+0000] {taskinstance.py:2076} INFO - Dependencies all met for dep_context=non-requeueable deps ti=<TaskInstance: fill_data.task scheduled__2024-06-17T00:00:00+00:00 [queued]>
[2024-06-24T22:03:42.991+0000] {taskinstance.py:2076} INFO - Dependencies all met for dep_context=requeueable deps ti=<TaskInstance: fill_data.task scheduled__2024-06-17T00:00:00+00:00 [queued]>
[2024-06-24T22:03:42.991+0000] {taskinstance.py:2306} INFO - Starting attempt 1 of 1
[2024-06-24T22:03:42.996+0000] {taskinstance.py:2330} INFO - Executing <Task(PythonOperator): task> on 2024-06-17 00:00:00+00:00
[2024-06-24T22:03:42.997+0000] {standard_task_runner.py:63} INFO - Started process 336 to run task
[2024-06-24T22:03:42.998+0000] {standard_task_runner.py:90} INFO - Running: ['airflow', 'tasks', 'run', 'fill_data', 'task', 'scheduled__2024-06-17T00:00:00+00:00', '--job-id', '26', '--raw', '--subdir', 'DAGS_FOLDER/fill_data.py', '--cfg-path', '/tmp/tmpmjh0i6j0']
[2024-06-24T22:03:42.999+0000] {standard_task_runner.py:91} INFO - Job 26: Subtask task
[2024-06-24T22:03:43.011+0000] {task_command.py:426} INFO - Running <TaskInstance: fill_data.task scheduled__2024-06-17T00:00:00+00:00 [running]> on host 8159af6655a2
[2024-06-24T22:03:43.031+0000] {taskinstance.py:2648} INFO - Exporting env vars: AIRFLOW_CTX_DAG_OWNER='airflow' AIRFLOW_CTX_DAG_ID='fill_data' AIRFLOW_CTX_TASK_ID='task' AIRFLOW_CTX_EXECUTION_DATE='2024-06-17T00:00:00+00:00' AIRFLOW_CTX_TRY_NUMBER='1' AIRFLOW_CTX_DAG_RUN_ID='scheduled__2024-06-17T00:00:00+00:00'
[2024-06-24T22:03:43.031+0000] {taskinstance.py:430} INFO - ::endgroup::
[2024-06-24T22:03:43.049+0000] {taskinstance.py:441} INFO - ::group::Post task execution logs
[2024-06-24T22:03:43.050+0000] {taskinstance.py:2905} ERROR - Task failed with exception
Traceback (most recent call last):
  File "/usr/local/lib/python3.11/site-packages/airflow/models/taskinstance.py", line 465, in _execute_task
    result = _execute_callable(context=context, **execute_callable_kwargs)
             ^^^^^^^^^^^^^^^^^^^^^^^^^^^^^^^^^^^^^^^^^^^^^^^^^^^^^^^^^^^^^
  File "/usr/local/lib/python3.11/site-packages/airflow/models/taskinstance.py", line 432, in _execute_callable
    return execute_callable(context=context, **execute_callable_kwargs)
           ^^^^^^^^^^^^^^^^^^^^^^^^^^^^^^^^^^^^^^^^^^^^^^^^^^^^^^^^^^^^
  File "/usr/local/lib/python3.11/site-packages/airflow/models/baseoperator.py", line 400, in wrapper
    return func(self, *args, **kwargs)
           ^^^^^^^^^^^^^^^^^^^^^^^^^^^
  File "/usr/local/lib/python3.11/site-packages/airflow/operators/python.py", line 235, in execute
    return_value = self.execute_callable()
                   ^^^^^^^^^^^^^^^^^^^^^^^
  File "/usr/local/lib/python3.11/site-packages/airflow/operators/python.py", line 252, in execute_callable
    return self.python_callable(*self.op_args, **self.op_kwargs)
           ^^^^^^^^^^^^^^^^^^^^^^^^^^^^^^^^^^^^^^^^^^^^^^^^^^^^^
  File "/opt/airflow/dags/fill_data.py", line 198, in generate_data
    people = generator.generate_people(100)
             ^^^^^^^^^^^^^^^^^^^^^^^^^
AttributeError: 'DataGenerator' object has no attribute 'generate_people'
[2024-06-24T22:03:43.051+0000] {taskinstance.py:1206} INFO - Marking task as FAILED. dag_id=fill_data, task_id=task, run_id=scheduled__2024-06-17T00:00:00+00:00, execution_date=20240617T000000, start_date=20240624T220342, end_date=20240624T220343
[2024-06-24T22:03:43.055+0000] {standard_task_runner.py:110} ERROR - Failed to execute job 26 for task task ('DataGenerator' object has no attribute 'generate_people'; 336)
[2024-06-24T22:03:43.097+0000] {local_task_job_runner.py:240} INFO - Task exited with return code 1
[2024-06-24T22:03:43.102+0000] {taskinstance.py:3498} INFO - 0 downstream tasks scheduled from follow-on schedule check
[2024-06-24T22:03:43.102+0000] {local_task_job_runner.py:222} INFO - ::endgroup::
